Workbook

Sheet EV_Stations
A1: station_id | B1: plug_id | C1: station_name | D1: operator | E1: address | F1: city | G1: district | H1: province | I1: connector_type | J1: charging_mode | K1: power_kw_dc | L1: power_kw_ac | M1: power_kw_max | N1: power_source_detail | O1: plug_count | P1: contact | Q1: map_url | R1: status | S1: rating | T1: source | U1: verified | V1: assumption_flag | W1: last_verified | X1: contact_best | Y1: contact_basis | Z1: contact_clean | AA1: contact_core | AB1: contact_national | AC1: contact_e164 | AD1: contact_type | AE1: contact_format_check
A2: EVNP-0001 | B2: EVNP-0001-P1 | C2: Abukhaireni | D2: NEA | E2: Abukhaireni | F2: Abukhaireni | G2: {=IFERROR(INDEX(City_Lookup!$B$2:$B$297,MATCH(TRUE,ISNUMBER(SEARCH(City_Lookup!$A$2:$A$297,$F2&" "&$E2)),0)),"Not Available")} -> Tanahun | H2: =IFERROR(INDEX(City_Lookup!$E$2:$E$66,MATCH($G2,City_Lookup!$D$2:$D$66,0)),"Not Available") -> Gandaki | I2: CCS2 | J2: DC | K2: 120.0 | M2: 120.0 | N2: plug_type='CCS2' | power_type='120Kw - DC, 22Kw - AC' | O2: 2 | P2: Not Available | Q2: https://www.google.com/maps/search/?api=1&query=Abukhaireni%2C%20Abukhaireni | R2: Listed | S2: Not Available | T2: chargingstationsnepal.com (workbook: EV_Station_Data.xlsx, brand/partner network compilation) | U2: NO | V2: YES | W2: 2026-09-03 | X2: +977-1-4153051 | Y2: Operator hotline (web, not station-specific) | Z2: =IF($X2="Not Available","",TRIM(LEFT(SUBSTITUTE(SUBSTITUTE(SUBSTITUTE(SUBSTITUTE(SUBSTITUTE(SUBSTITUTE(SUBSTITUTE($X2," ",""),"-",""),"(",""),")",""),".",""),"+","")&"/","/",REPT(" ",60)),60))) -> 97714153051 | AA2: =IF($Z2="","",IF(ISNUMBER(-$Z2),IF(LEFT($Z2,3)="977",MID($Z2,4,20),$Z2),IF(ISNUMBER(SEARCH("977",$Z2)),MID($Z2,SEARCH("977",$Z2)+3,20),$Z2))) -> 14153051 | AB2: =IF($AA2="","",IF(LEFT($AA2,1)="0",MID($AA2,2,20),$AA2)) -> 14153051 | AC2: =IF($AB2="","Not Available","+977"&$AB2) -> +97714153051 | AD2: =IF($AB2="","Not Available",IF(AND(LEN($AB2)=10,LEFT($AB2,1)="9"),"Mobile",IF(AND(LEN($AB2)>=8,LEN($AB2)<=9),IF(ISNUMBER(SEARCH("/",$X2)),"Landline (multiple lines)","Landline"),"Unrecognised"))) -> Landline | AE2: =IF($AB2="","Not Available",IF(AND(ISNUMBER(-$AB2),$AD2<>"Unrecognised"),"Valid","Check format")) -> Valid
A3: EVNP-0001 | B3: EVNP-0001-P2 | C3: Abukhaireni | D3: NEA | E3: Abukhaireni | F3: Abukhaireni | G3: {=IFERROR(INDEX(City_Lookup!$B$2:$B$297,MATCH(TRUE,ISNUMBER(SEARCH(City_Lookup!$A$2:$A$297,$F3&" "&$E3)),0)),"Not Available")} -> Tanahun | H3: =IFERROR(INDEX(City_Lookup!$E$2:$E$66,MATCH($G3,City_Lookup!$D$2:$D$66,0)),"Not Available") -> Gandaki | I3: CCS2 | J3: AC | L3: 22.0 | M3: 22.0 | N3: plug_type='CCS2' | power_type='120Kw - DC, 22Kw - AC' | O3: 2 | P3: Not Available | Q3: https://www.google.com/maps/search/?api=1&query=Abukhaireni%2C%20Abukhaireni | R3: Listed | S3: Not Available | T3: chargingstationsnepal.com (workbook: EV_Station_Data.xlsx, brand/partner network compilation) | U3: NO | V3: YES | W3: 2026-09-03 | X3: +977-1-4153051 | Y3: Operator hotline (web, not station-specific) | Z3: =IF($X3="Not Available","",TRIM(LEFT(SUBSTITUTE(SUBSTITUTE(SUBSTITUTE(SUBSTITUTE(SUBSTITUTE(SUBSTITUTE(SUBSTITUTE($X3," ",""),"-",""),"(",""),")",""),".",""),"+","")&"/","/",REPT(" ",60)),60))) -> 97714153051 | AA3: =IF($Z3="","",IF(ISNUMBER(-$Z3),IF(LEFT($Z3,3)="977",MID($Z3,4,20),$Z3),IF(ISNUMBER(SEARCH("977",$Z3)),MID($Z3,SEARCH("977",$Z3)+3,20),$Z3))) -> 14153051 | AB3: =IF($AA3="","",IF(LEFT($AA3,1)="0",MID($AA3,2,20),$AA3)) -> 14153051 | AC3: =IF($AB3="","Not Available","+977"&$AB3) -> +97714153051 | AD3: =IF($AB3="","Not Available",IF(AND(LEN($AB3)=10,LEFT($AB3,1)="9"),"Mobile",IF(AND(LEN($AB3)>=8,LEN($AB3)<=9),IF(ISNUMBER(SEARCH("/",$X3)),"Landline (multiple lines)","Landline"),"Unrecognised"))) -> Landline | AE3: =IF($AB3="","Not Available",IF(AND(ISNUMBER(-$AB3),$AD3<>"Unrecognised"),"Valid","Check format")) -> Valid
A4: EVNP-0002 | B4: EVNP-0002-P1 | C4: Kurintar | D4: NEA | E4: Kurintar | F4: Kurintar | G4: {=IFERROR(INDEX(City_Lookup!$B$2:$B$297,MATCH(TRUE,ISNUMBER(SEARCH(City_Lookup!$A$2:$A$297,$F4&" "&$E4)),0)),"Not Available")} -> Chitwan | H4: =IFERROR(INDEX(City_Lookup!$E$2:$E$66,MATCH($G4,City_Lookup!$D$2:$D$66,0)),"Not Available") -> Bagmati | I4: CCS2 | J4: DC | K4: 120.0 | M4: 120.0 | N4: plug_type='CCS2' | power_type='120Kw - DC, 22Kw - AC' | O4: 2 | P4: Not Available | Q4: https://www.google.com/maps/search/?api=1&query=Kurintar%2C%20Kurintar | R4: Listed | S4: Not Available | T4: chargingstationsnepal.com (workbook: EV_Station_Data.xlsx, brand/partner network compilation) | U4: NO | V4: YES | W4: 2026-09-03 | X4: +977-1-4153051 | Y4: Operator hotline (web, not station-specific) | Z4: =IF($X4="Not Available","",TRIM(LEFT(SUBSTITUTE(SUBSTITUTE(SUBSTITUTE(SUBSTITUTE(SUBSTITUTE(SUBSTITUTE(SUBSTITUTE($X4," ",""),"-",""),"(",""),")",""),".",""),"+","")&"/","/",REPT(" ",60)),60))) -> 97714153051 | AA4: =IF($Z4="","",IF(ISNUMBER(-$Z4),IF(LEFT($Z4,3)="977",MID($Z4,4,20),$Z4),IF(ISNUMBER(SEARCH("977",$Z4)),MID($Z4,SEARCH("977",$Z4)+3,20),$Z4))) -> 14153051 | AB4: =IF($AA4="","",IF(LEFT($AA4,1)="0",MID($AA4,2,20),$AA4)) -> 14153051 | AC4: =IF($AB4="","Not Available","+977"&$AB4) -> +97714153051 | AD4: =IF($AB4="","Not Available",IF(AND(LEN($AB4)=10,LEFT($AB4,1)="9"),"Mobile",IF(AND(LEN($AB4)>=8,LEN($AB4)<=9),IF(ISNUMBER(SEARCH("/",$X4)),"Landline (multiple lines)","Landline"),"Unrecognised"))) -> Landline | AE4: =IF($AB4="","Not Available",IF(AND(ISNUMBER(-$AB4),$AD4<>"Unrecognised"),"Valid","Check format")) -> Valid
A5: EVNP-0002 | B5: EVNP-0002-P2 | C5: Kurintar | D5: NEA | E5: Kurintar | F5: Kurintar | G5: {=IFERROR(INDEX(City_Lookup!$B$2:$B$297,MATCH(TRUE,ISNUMBER(SEARCH(City_Lookup!$A$2:$A$297,$F5&" "&$E5)),0)),"Not Available")} -> Chitwan | H5: =IFERROR(INDEX(City_Lookup!$E$2:$E$66,MATCH($G5,City_Lookup!$D$2:$D$66,0)),"Not Available") -> Bagmati | I5: CCS2 | J5: AC | L5: 22.0 | M5: 22.0 | N5: plug_type='CCS2' | power_type='120Kw - DC, 22Kw - AC' | O5: 2 | P5: Not Available | Q5: https://www.google.com/maps/search/?api=1&query=Kurintar%2C%20Kurintar | R5: Listed | S5: Not Available | T5: chargingstationsnepal.com (workbook: EV_Station_Data.xlsx, brand/partner network compilation) | U5: NO | V5: YES | W5: 2026-09-03 | X5: +977-1-4153051 | Y5: Operator hotline (web, not station-specific) | Z5: =IF($X5="Not Available","",TRIM(LEFT(SUBSTITUTE(SUBSTITUTE(SUBSTITUTE(SUBSTITUTE(SUBSTITUTE(SUBSTITUTE(SUBSTITUTE($X5," ",""),"-",""),"(",""),")",""),".",""),"+","")&"/","/",REPT(" ",60)),60))) -> 97714153051 | AA5: =IF($Z5="","",IF(ISNUMBER(-$Z5),IF(LEFT($Z5,3)="977",MID($Z5,4,20),$Z5),IF(ISNUMBER(SEARCH("977",$Z5)),MID($Z5,SEARCH("977",$Z5)+3,20),$Z5))) -> 14153051 | AB5: =IF($AA5="","",IF(LEFT($AA5,1)="0",MID($AA5,2,20),$AA5)) -> 14153051 | AC5: =IF($AB5="","Not Available","+977"&$AB5) -> +97714153051 | AD5: =IF($AB5="","Not Available",IF(AND(LEN($AB5)=10,LEFT($AB5,1)="9"),"Mobile",IF(AND(LEN($AB5)>=8,LEN($AB5)<=9),IF(ISNUMBER(SEARCH("/",$X5)),"Landline (multiple lines)","Landline"),"Unrecognised"))) -> Landline | AE5: =IF($AB5="","Not Available",IF(AND(ISNUMBER(-$AB5),$AD5<>"Unrecognised"),"Valid","Check format")) -> Valid
A6: EVNP-0003 | B6: EVNP-0003-P1 | C6: Charaudi | D6: NEA | E6: Charaudi | F6: Charaudi | G6: {=IFERROR(INDEX(City_Lookup!$B$2:$B$297,MATCH(TRUE,ISNUMBER(SEARCH(City_Lookup!$A$2:$A$297,$F6&" "&$E6)),0)),"Not Available")} -> Dhading | H6: =IFERROR(INDEX(City_Lookup!$E$2:$E$66,MATCH($G6,City_Lookup!$D$2:$D$66,0)),"Not Available") -> Bagmati | I6: CCS2 | J6: DC | K6: 120.0 | M6: 120.0 | N6: plug_type='CCS2' | power_type='120Kw - DC, 22Kw - AC' | O6: 2 | P6: Not Available | Q6: https://www.google.com/maps/search/?api=1&query=Charaudi%2C%20Charaudi | R6: Listed | S6: Not Available | T6: chargingstationsnepal.com (workbook: EV_Station_Data.xlsx, brand/partner network compilation) | U6: NO | V6: YES | W6: 2026-09-03 | X6: +977-1-4153051 | Y6: Operator hotline (web, not station-specific) | Z6: =IF($X6="Not Available","",TRIM(LEFT(SUBSTITUTE(SUBSTITUTE(SUBSTITUTE(SUBSTITUTE(SUBSTITUTE(SUBSTITUTE(SUBSTITUTE($X6," ",""),"-",""),"(",""),")",""),".",""),"+","")&"/","/",REPT(" ",60)),60))) -> 97714153051 | AA6: =IF($Z6="","",IF(ISNUMBER(-$Z6),IF(LEFT($Z6,3)="977",MID($Z6,4,20),$Z6),IF(ISNUMBER(SEARCH("977",$Z6)),MID($Z6,SEARCH("977",$Z6)+3,20),$Z6))) -> 14153051 | AB6: =IF($AA6="","",IF(LEFT($AA6,1)="0",MID($AA6,2,20),$AA6)) -> 14153051 | AC6: =IF($AB6="","Not Available","+977"&$AB6) -> +97714153051 | AD6: =IF($AB6="","Not Available",IF(AND(LEN($AB6)=10,LEFT($AB6,1)="9"),"Mobile",IF(AND(LEN($AB6)>=8,LEN($AB6)<=9),IF(ISNUMBER(SEARCH("/",$X6)),"Landline (multiple lines)","Landline"),"Unrecognised"))) -> Landline | AE6: =IF($AB6="","Not Available",IF(AND(ISNUMBER(-$AB6),$AD6<>"Unrecognised"),"Valid","Check format")) -> Valid
A7: EVNP-0003 | B7: EVNP-0003-P2 | C7: Charaudi | D7: NEA | E7: Charaudi | F7: Charaudi | G7: {=IFERROR(INDEX(City_Lookup!$B$2:$B$297,MATCH(TRUE,ISNUMBER(SEARCH(City_Lookup!$A$2:$A$297,$F7&" "&$E7)),0)),"Not Available")} -> Dhading | H7: =IFERROR(INDEX(City_Lookup!$E$2:$E$66,MATCH($G7,City_Lookup!$D$2:$D$66,0)),"Not Available") -> Bagmati | I7: CCS2 | J7: AC | L7: 22.0 | M7: 22.0 | N7: plug_type='CCS2' | power_type='120Kw - DC, 22Kw - AC' | O7: 2 | P7: Not Available | Q7: https://www.google.com/maps/search/?api=1&query=Charaudi%2C%20Charaudi | R7: Listed | S7: Not Available | T7: chargingstationsnepal.com (workbook: EV_Station_Data.xlsx, brand/partner network compilation) | U7: NO | V7: YES | W7: 2026-09-03 | X7: +977-1-4153051 | Y7: Operator hotline (web, not station-specific) | Z7: =IF($X7="Not Available","",TRIM(LEFT(SUBSTITUTE(SUBSTITUTE(SUBSTITUTE(SUBSTITUTE(SUBSTITUTE(SUBSTITUTE(SUBSTITUTE($X7," ",""),"-",""),"(",""),")",""),".",""),"+","")&"/","/",REPT(" ",60)),60))) -> 97714153051 | AA7: =IF($Z7="","",IF(ISNUMBER(-$Z7),IF(LEFT($Z7,3)="977",MID($Z7,4,20),$Z7),IF(ISNUMBER(SEARCH("977",$Z7)),MID($Z7,SEARCH("977",$Z7)+3,20),$Z7))) -> 14153051 | AB7: =IF($AA7="","",IF(LEFT($AA7,1)="0",MID($AA7,2,20),$AA7)) -> 14153051 | AC7: =IF($AB7="","Not Available","+977"&$AB7) -> +97714153051 | AD7: =IF($AB7="","Not Available",IF(AND(LEN($AB7)=10,LEFT($AB7,1)="9"),"Mobile",IF(AND(LEN($AB7)>=8,LEN($AB7)<=9),IF(ISNUMBER(SEARCH("/",$X7)),"Landline (multiple lines)","Landline"),"Unrecognised"))) -> Landline | AE7: =IF($AB7="","Not Available",IF(AND(ISNUMBER(-$AB7),$AD7<>"Unrecognised"),"Valid","Check format")) -> Valid
A8: EVNP-0004 | B8: EVNP-0004-P1 | C8: Dolakha | D8: NEA | E8: Dolakha | F8: Dolakha | G8: {=IFERROR(INDEX(City_Lookup!$B$2:$B$297,MATCH(TRUE,ISNUMBER(SEARCH(City_Lookup!$A$2:$A$297,$F8&" "&$E8)),0)),"Not Available")} -> Dolakha | H8: =IFERROR(INDEX(City_Lookup!$E$2:$E$66,MATCH($G8,City_Lookup!$D$2:$D$66,0)),"Not Available") -> Bagmati | I8: CCS2 | J8: DC | K8: 120.0 | M8: 120.0 | N8: plug_type='CCS2' | power_type='120Kw - DC, 22Kw - AC' | O8: 2 | P8: Not Available | Q8: https://www.google.com/maps/search/?api=1&query=Dolakha%2C%20Dolakha | R8: Listed | S8: Not Available | T8: chargingstationsnepal.com (workbook: EV_Station_Data.xlsx, brand/partner network compilation) | U8: NO | V8: YES | W8: 2026-09-03 | X8: +977-1-4153051 | Y8: Operator hotline (web, not station-specific) | Z8: =IF($X8="Not Available","",TRIM(LEFT(SUBSTITUTE(SUBSTITUTE(SUBSTITUTE(SUBSTITUTE(SUBSTITUTE(SUBSTITUTE(SUBSTITUTE($X8," ",""),"-",""),"(",""),")",""),".",""),"+","")&"/","/",REPT(" ",60)),60))) -> 97714153051 | AA8: =IF($Z8="","",IF(ISNUMBER(-$Z8),IF(LEFT($Z8,3)="977",MID($Z8,4,20),$Z8),IF(ISNUMBER(SEARCH("977",$Z8)),MID($Z8,SEARCH("977",$Z8)+3,20),$Z8))) -> 14153051 | AB8: =IF($AA8="","",IF(LEFT($AA8,1)="0",MID($AA8,2,20),$AA8)) -> 14153051 | AC8: =IF($AB8="","Not Available","+977"&$AB8) -> +97714153051 | AD8: =IF($AB8="","Not Available",IF(AND(LEN($AB8)=10,LEFT($AB8,1)="9"),"Mobile",IF(AND(LEN($AB8)>=8,LEN($AB8)<=9),IF(ISNUMBER(SEARCH("/",$X8)),"Landline (multiple lines)","Landline"),"Unrecognised"))) -> Landline | AE8: =IF($AB8="","Not Available",IF(AND(ISNUMBER(-$AB8),$AD8<>"Unrecognised"),"Valid","Check format")) -> Valid
A9: EVNP-0004 | B9: EVNP-0004-P2 | C9: Dolakha | D9: NEA | E9: Dolakha | F9: Dolakha | G9: {=IFERROR(INDEX(City_Lookup!$B$2:$B$297,MATCH(TRUE,ISNUMBER(SEARCH(City_Lookup!$A$2:$A$297,$F9&" "&$E9)),0)),"Not Available")} -> Dolakha | H9: =IFERROR(INDEX(City_Lookup!$E$2:$E$66,MATCH($G9,City_Lookup!$D$2:$D$66,0)),"Not Available") -> Bagmati | I9: CCS2 | J9: AC | L9: 22.0 | M9: 22.0 | N9: plug_type='CCS2' | power_type='120Kw - DC, 22Kw - AC' | O9: 2 | P9: Not Available | Q9: https://www.google.com/maps/search/?api=1&query=Dolakha%2C%20Dolakha | R9: Listed | S9: Not Available | T9: chargingstationsnepal.com (workbook: EV_Station_Data.xlsx, brand/partner network compilation) | U9: NO | V9: YES | W9: 2026-09-03 | X9: +977-1-4153051 | Y9: Operator hotline (web, not station-specific) | Z9: =IF($X9="Not Available","",TRIM(LEFT(SUBSTITUTE(SUBSTITUTE(SUBSTITUTE(SUBSTITUTE(SUBSTITUTE(SUBSTITUTE(SUBSTITUTE($X9," ",""),"-",""),"(",""),")",""),".",""),"+","")&"/","/",REPT(" ",60)),60))) -> 97714153051 | AA9: =IF($Z9="","",IF(ISNUMBER(-$Z9),IF(LEFT($Z9,3)="977",MID($Z9,4,20),$Z9),IF(ISNUMBER(SEARCH("977",$Z9)),MID($Z9,SEARCH("977",$Z9)+3,20),$Z9))) -> 14153051 | AB9: =IF($AA9="","",IF(LEFT($AA9,1)="0",MID($AA9,2,20),$AA9)) -> 14153051 | AC9: =IF($AB9="","Not Available","+977"&$AB9) -> +97714153051 | AD9: =IF($AB9="","Not Available",IF(AND(LEN($AB9)=10,LEFT($AB9,1)="9"),"Mobile",IF(AND(LEN($AB9)>=8,LEN($AB9)<=9),IF(ISNUMBER(SEARCH("/",$X9)),"Landline (multiple lines)","Landline"),"Unrecognised"))) -> Landline | AE9: =IF($AB9="","Not Available",IF(AND(ISNUMBER(-$AB9),$AD9<>"Unrecognised"),"Valid","Check format")) -> Valid
A10: EVNP-0005 | B10: EVNP-0005-P1 | C10: Dhulikhel | D10: NEA | E10: Dhulikhel | F10: Dhulikhel | G10: {=IFERROR(INDEX(City_Lookup!$B$2:$B$297,MATCH(TRUE,ISNUMBER(SEARCH(City_Lookup!$A$2:$A$297,$F10&" "&$E10)),0)),"Not Available")} -> Kavre | H10: =IFERROR(INDEX(City_Lookup!$E$2:$E$66,MATCH($G10,City_Lookup!$D$2:$D$66,0)),"Not Available") -> Bagmati | I10: CCS2 | J10: DC | K10: 120.0 | M10: 120.0 | N10: plug_type='CCS2' | power_type='120Kw - DC, 22Kw - AC' | O10: 2 | P10: Not Available | Q10: https://www.google.com/maps/search/?api=1&query=Dhulikhel%2C%20Dhulikhel | R10: Listed | S10: Not Available | T10: chargingstationsnepal.com (workbook: EV_Station_Data.xlsx, brand/partner network compilation) | U10: NO | V10: YES | W10: 2026-09-03 | X10: +977-1-4153051 | Y10: Operator hotline (web, not station-specific) | Z10: =IF($X10="Not Available","",TRIM(LEFT(SUBSTITUTE(SUBSTITUTE(SUBSTITUTE(SUBSTITUTE(SUBSTITUTE(SUBSTITUTE(SUBSTITUTE($X10," ",""),"-",""),"(",""),")",""),".",""),"+","")&"/","/",REPT(" ",60)),60))) -> 97714153051 | AA10: =IF($Z10="","",IF(ISNUMBER(-$Z10),IF(LEFT($Z10,3)="977",MID($Z10,4,20),$Z10),IF(ISNUMBER(SEARCH("977",$Z10)),MID($Z10,SEARCH("977",$Z10)+3,20),$Z10))) -> 14153051 | AB10: =IF($AA10="","",IF(LEFT($AA10,1)="0",MID($AA10,2,20),$AA10)) -> 14153051 | AC10: =IF($AB10="","Not Available","+977"&$AB10) -> +97714153051 | AD10: =IF($AB10="","Not Available",IF(AND(LEN($AB10)=10,LEFT($AB10,1)="9"),"Mobile",IF(AND(LEN($AB10)>=8,LEN($AB10)<=9),IF(ISNUMBER(SEARCH("/",$X10)),"Landline (multiple lines)","Landline"),"Unrecognised"))) -> Landline | AE10: =IF($AB10="","Not Available",IF(AND(ISNUMBER(-$AB10),$AD10<>"Unrecognised"),"Valid","Check format")) -> Valid
A11: EVNP-0005 | B11: EVNP-0005-P2 | C11: Dhulikhel | D11: NEA | E11: Dhulikhel | F11: Dhulikhel | G11: {=IFERROR(INDEX(City_Lookup!$B$2:$B$297,MATCH(TRUE,ISNUMBER(SEARCH(City_Lookup!$A$2:$A$297,$F11&" "&$E11)),0)),"Not Available")} -> Kavre | H11: =IFERROR(INDEX(City_Lookup!$E$2:$E$66,MATCH($G11,City_Lookup!$D$2:$D$66,0)),"Not Available") -> Bagmati | I11: CCS2 | J11: AC | L11: 22.0 | M11: 22.0 | N11: plug_type='CCS2' | power_type='120Kw - DC, 22Kw - AC' | O11: 2 | P11: Not Available | Q11: https://www.google.com/maps/search/?api=1&query=Dhulikhel%2C%20Dhulikhel | R11: Listed | S11: Not Available | T11: chargingstationsnepal.com (workbook: EV_Station_Data.xlsx, brand/partner network compilation) | U11: NO | V11: YES | W11: 2026-09-03 | X11: +977-1-4153051 | Y11: Operator hotline (web, not station-specific) | Z11: =IF($X11="Not Available","",TRIM(LEFT(SUBSTITUTE(SUBSTITUTE(SUBSTITUTE(SUBSTITUTE(SUBSTITUTE(SUBSTITUTE(SUBSTITUTE($X11," ",""),"-",""),"(",""),")",""),".",""),"+","")&"/","/",REPT(" ",60)),60))) -> 97714153051 | AA11: =IF($Z11="","",IF(ISNUMBER(-$Z11),IF(LEFT($Z11,3)="977",MID($Z11,4,20),$Z11),IF(ISNUMBER(SEARCH("977",$Z11)),MID($Z11,SEARCH("977",$Z11)+3,20),$Z11))) -> 14153051 | AB11: =IF($AA11="","",IF(LEFT($AA11,1)="0",MID($AA11,2,20),$AA11)) -> 14153051 | AC11: =IF($AB11="","Not Available","+977"&$AB11) -> +97714153051 | AD11: =IF($AB11="","Not Available",IF(AND(LEN($AB11)=10,LEFT($AB11,1)="9"),"Mobile",IF(AND(LEN($AB11)>=8,LEN($AB11)<=9),IF(ISNUMBER(SEARCH("/",$X11)),"Landline (multiple lines)","Landline"),"Unrecognised"))) -> Landline | AE11: =IF($AB11="","Not Available",IF(AND(ISNUMBER(-$AB11),$AD11<>"Unrecognised"),"Valid","Check format")) -> Valid
A12: EVNP-0006 | B12: EVNP-0006-P1 | C12: Dharke | D12: NEA | E12: Dharke | F12: Dharke | G12: {=IFERROR(INDEX(City_Lookup!$B$2:$B$297,MATCH(TRUE,ISNUMBER(SEARCH(City_Lookup!$A$2:$A$297,$F12&" "&$E12)),0)),"Not Available")} -> Dhading | H12: =IFERROR(INDEX(City_Lookup!$E$2:$E$66,MATCH($G12,City_Lookup!$D$2:$D$66,0)),"Not Available") -> Bagmati | I12: CCS2 | J12: DC | K12: 120.0 | M12: 120.0 | N12: plug_type='CCS2' | power_type='120Kw - DC, 22Kw - AC' | O12: 2 | P12: Not Available | Q12: https://www.google.com/maps/search/?api=1&query=Dharke%2C%20Dharke | R12: Listed | S12: Not Available | T12: chargingstationsnepal.com (workbook: EV_Station_Data.xlsx, brand/partner network compilation) | U12: NO | V12: YES | W12: 2026-09-03 | X12: +977-1-4153051 | Y12: Operator hotline (web, not station-specific) | Z12: =IF($X12="Not Available","",TRIM(LEFT(SUBSTITUTE(SUBSTITUTE(SUBSTITUTE(SUBSTITUTE(SUBSTITUTE(SUBSTITUTE(SUBSTITUTE($X12," ",""),"-",""),"(",""),")",""),".",""),"+","")&"/","/",REPT(" ",60)),60))) -> 97714153051 | AA12: =IF($Z12="","",IF(ISNUMBER(-$Z12),IF(LEFT($Z12,3)="977",MID($Z12,4,20),$Z12),IF(ISNUMBER(SEARCH("977",$Z12)),MID($Z12,SEARCH("977",$Z12)+3,20),$Z12))) -> 14153051 | AB12: =IF($AA12="","",IF(LEFT($AA12,1)="0",MID($AA12,2,20),$AA12)) -> 14153051 | AC12: =IF($AB12="","Not Available","+977"&$AB12) -> +97714153051 | AD12: =IF($AB12="","Not Available",IF(AND(LEN($AB12)=10,LEFT($AB12,1)="9"),"Mobile",IF(AND(LEN($AB12)>=8,LEN($AB12)<=9),IF(ISNUMBER(SEARCH("/",$X12)),"Landline (multiple lines)","Landline"),"Unrecognised"))) -> Landline | AE12: =IF($AB12="","Not Available",IF(AND(ISNUMBER(-$AB12),$AD12<>"Unrecognised"),"Valid","Check format")) -> Valid
A13: EVNP-0006 | B13: EVNP-0006-P2 | C13: Dharke | D13: NEA | E13: Dharke | F13: Dharke | G13: {=IFERROR(INDEX(City_Lookup!$B$2:$B$297,MATCH(TRUE,ISNUMBER(SEARCH(City_Lookup!$A$2:$A$297,$F13&" "&$E13)),0)),"Not Available")} -> Dhading | H13: =IFERROR(INDEX(City_Lookup!$E$2:$E$66,MATCH($G13,City_Lookup!$D$2:$D$66,0)),"Not Available") -> Bagmati | I13: CCS2 | J13: AC | L13: 22.0 | M13: 22.0 | N13: plug_type='CCS2' | power_type='120Kw - DC, 22Kw - AC' | O13: 2 | P13: Not Available | Q13: https://www.google.com/maps/search/?api=1&query=Dharke%2C%20Dharke | R13: Listed | S13: Not Available | T13: chargingstationsnepal.com (workbook: EV_Station_Data.xlsx, brand/partner network compilation) | U13: NO | V13: YES | W13: 2026-09-03 | X13: +977-1-4153051 | Y13: Operator hotline (web, not station-specific) | Z13: =IF($X13="Not Available","",TRIM(LEFT(SUBSTITUTE(SUBSTITUTE(SUBSTITUTE(SUBSTITUTE(SUBSTITUTE(SUBSTITUTE(SUBSTITUTE($X13," ",""),"-",""),"(",""),")",""),".",""),"+","")&"/","/",REPT(" ",60)),60))) -> 97714153051 | AA13: =IF($Z13="","",IF(ISNUMBER(-$Z13),IF(LEFT($Z13,3)="977",MID($Z13,4,20),$Z13),IF(ISNUMBER(SEARCH("977",$Z13)),MID($Z13,SEARCH("977",$Z13)+3,20),$Z13))) -> 14153051 | AB13: =IF($AA13="","",IF(LEFT($AA13,1)="0",MID($AA13,2,20),$AA13)) -> 14153051 | AC13: =IF($AB13="","Not Available","+977"&$AB13) -> +97714153051 | AD13: =IF($AB13="","Not Available",IF(AND(LEN($AB13)=10,LEFT($AB13,1)="9"),"Mobile",IF(AND(LEN($AB13)>=8,LEN($AB13)<=9),IF(ISNUMBER(SEARCH("/",$X13)),"Landline (multiple lines)","Landline"),"Unrecognised"))) -> Landline | AE13: =IF($AB13="","Not Available",IF(AND(ISNUMBER(-$AB13),$AD13<>"Unrecognised"),"Valid","Check format")) -> Valid
A14: EVNP-0007 | B14: EVNP-0007-P1 | C14: Mugling | D14: NEA | E14: Mugling | F14: Mugling | G14: {=IFERROR(INDEX(City_Lookup!$B$2:$B$297,MATCH(TRUE,ISNUMBER(SEARCH(City_Lookup!$A$2:$A$297,$F14&" "&$E14)),0)),"Not Available")} -> Chitwan | H14: =IFERROR(INDEX(City_Lookup!$E$2:$E$66,MATCH($G14,City_Lookup!$D$2:$D$66,0)),"Not Available") -> Bagmati | I14: CCS2 | J14: DC | K14: 120.0 | M14: 120.0 | N14: plug_type='CCS2' | power_type='120Kw - DC, 22Kw - AC' | O14: 2 | P14: Not Available | Q14: https://www.google.com/maps/search/?api=1&query=Mugling%2C%20Mugling | R14: Listed | S14: Not Available | T14: chargingstationsnepal.com (workbook: EV_Station_Data.xlsx, brand/partner network compilation) | U14: NO | V14: YES | W14: 2026-09-03 | X14: +977-1-4153051 | Y14: Operator hotline (web, not station-specific) | Z14: =IF($X14="Not Available","",TRIM(LEFT(SUBSTITUTE(SUBSTITUTE(SUBSTITUTE(SUBSTITUTE(SUBSTITUTE(SUBSTITUTE(SUBSTITUTE($X14," ",""),"-",""),"(",""),")",""),".",""),"+","")&"/","/",REPT(" ",60)),60))) -> 97714153051 | AA14: =IF($Z14="","",IF(ISNUMBER(-$Z14),IF(LEFT($Z14,3)="977",MID($Z14,4,20),$Z14),IF(ISNUMBER(SEARCH("977",$Z14)),MID($Z14,SEARCH("977",$Z14)+3,20),$Z14))) -> 14153051 | AB14: =IF($AA14="","",IF(LEFT($AA14,1)="0",MID($AA14,2,20),$AA14)) -> 14153051 | AC14: =IF($AB14="","Not Available","+977"&$AB14) -> +97714153051 | AD14: =IF($AB14="","Not Available",IF(AND(LEN($AB14)=10,LEFT($AB14,1)="9"),"Mobile",IF(AND(LEN($AB14)>=8,LEN($AB14)<=9),IF(ISNUMBER(SEARCH("/",$X14)),"Landline (multiple lines)","Landline"),"Unrecognised"))) -> Landline | AE14: =IF($AB14="","Not Available",IF(AND(ISNUMBER(-$AB14),$AD14<>"Unrecognised"),"Valid","Check format")) -> Valid
A15: EVNP-0007 | B15: EVNP-0007-P2 | C15: Mugling | D15: NEA | E15: Mugling | F15: Mugling | G15: {=IFERROR(INDEX(City_Lookup!$B$2:$B$297,MATCH(TRUE,ISNUMBER(SEARCH(City_Lookup!$A$2:$A$297,$F15&" "&$E15)),0)),"Not Available")} -> Chitwan | H15: =IFERROR(INDEX(City_Lookup!$E$2:$E$66,MATCH($G15,City_Lookup!$D$2:$D$66,0)),"Not Available") -> Bagmati | I15: CCS2 | J15: AC | L15: 22.0 | M15: 22.0 | N15: plug_type='CCS2' | power_type='120Kw - DC, 22Kw - AC' | O15: 2 | P15: Not Available | Q15: https://www.google.com/maps/search/?api=1&query=Mugling%2C%20Mugling | R15: Listed | S15: Not Available | T15: chargingstationsnepal.com (workbook: EV_Station_Data.xlsx, brand/partner network compilation) | U15: NO | V15: YES | W15: 2026-09-03 | X15: +977-1-4153051 | Y15: Operator hotline (web, not station-specific) | Z15: =IF($X15="Not Available","",TRIM(LEFT(SUBSTITUTE(SUBSTITUTE(SUBSTITUTE(SUBSTITUTE(SUBSTITUTE(SUBSTITUTE(SUBSTITUTE($X15," ",""),"-",""),"(",""),")",""),".",""),"+","")&"/","/",REPT(" ",60)),60))) -> 97714153051 | AA15: =IF($Z15="","",IF(ISNUMBER(-$Z15),IF(LEFT($Z15,3)="977",MID($Z15,4,20),$Z15),IF(ISNUMBER(SEARCH("977",$Z15)),MID($Z15,SEARCH("977",$Z15)+3,20),$Z15))) -> 14153051 | AB15: =IF($AA15="","",IF(LEFT($AA15,1)="0",MID($AA15,2,20),$AA15)) -> 14153051 | AC15: =IF($AB15="","Not Available","+977"&$AB15) -> +97714153051 | AD15: =IF($AB15="","Not Available",IF(AND(LEN($AB15)=10,LEFT($AB15,1)="9"),"Mobile",IF(AND(LEN($AB15)>=8,LEN($AB15)<=9),IF(ISNUMBER(SEARCH("/",$X15)),"Landline (multiple lines)","Landline"),"Unrecognised"))) -> Landline | AE15: =IF($AB15="","Not Available",IF(AND(ISNUMBER(-$AB15),$AD15<>"Unrecognised"),"Valid","Check format")) -> Valid
A16: EVNP-0008 | B16: EVNP-0008-P1 | C16: Paras Bus Park, Chitwan | D16: NEA | E16: Paras Bus Park, Chitwan | F16: Paras Bus Park, Chitwan | G16: {=IFERROR(INDEX(City_Lookup!$B$2:$B$297,MATCH(TRUE,ISNUMBER(SEARCH(City_Lookup!$A$2:$A$297,$F16&" "&$E16)),0)),"Not Available")} -> Chitwan | H16: =IFERROR(INDEX(City_Lookup!$E$2:$E$66,MATCH($G16,City_Lookup!$D$2:$D$66,0)),"Not Available") -> Bagmati | I16: CCS2 | J16: DC | K16: 120.0 | M16: 120.0 | N16: plug_type='CCS2' | power_type='120Kw - DC, 22Kw - AC' | O16: 2 | P16: Not Available | Q16: https://www.google.com/maps/search/?api=1&query=Paras%20Bus%20Park%2C%20Chitwan%2C%20Paras%20Bus%20Park%2C%20Chitwan | R16: Listed | S16: Not Available | T16: chargingstationsnepal.com (workbook: EV_Station_Data.xlsx, brand/partner network compilation) | U16: NO | V16: YES | W16: 2026-09-03 | X16: +977-1-4153051 | Y16: Operator hotline (web, not station-specific) | Z16: =IF($X16="Not Available","",TRIM(LEFT(SUBSTITUTE(SUBSTITUTE(SUBSTITUTE(SUBSTITUTE(SUBSTITUTE(SUBSTITUTE(SUBSTITUTE($X16," ",""),"-",""),"(",""),")",""),".",""),"+","")&"/","/",REPT(" ",60)),60))) -> 97714153051 | AA16: =IF($Z16="","",IF(ISNUMBER(-$Z16),IF(LEFT($Z16,3)="977",MID($Z16,4,20),$Z16),IF(ISNUMBER(SEARCH("977",$Z16)),MID($Z16,SEARCH("977",$Z16)+3,20),$Z16))) -> 14153051 | AB16: =IF($AA16="","",IF(LEFT($AA16,1)="0",MID($AA16,2,20),$AA16)) -> 14153051 | AC16: =IF($AB16="","Not Available","+977"&$AB16) -> +97714153051 | AD16: =IF($AB16="","Not Available",IF(AND(LEN($AB16)=10,LEFT($AB16,1)="9"),"Mobile",IF(AND(LEN($AB16)>=8,LEN($AB16)<=9),IF(ISNUMBER(SEARCH("/",$X16)),"Landline (multiple lines)","Landline"),"Unrecognised"))) -> Landline | AE16: =IF($AB16="","Not Available",IF(AND(ISNUMBER(-$AB16),$AD16<>"Unrecognised"),"Valid","Check format")) -> Valid
A17: EVNP-0008 | B17: EVNP-0008-P2 | C17: Paras Bus Park, Chitwan | D17: NEA | E17: Paras Bus Park, Chitwan | F17: Paras Bus Park, Chitwan | G17: {=IFERROR(INDEX(City_Lookup!$B$2:$B$297,MATCH(TRUE,ISNUMBER(SEARCH(City_Lookup!$A$2:$A$297,$F17&" "&$E17)),0)),"Not Available")} -> Chitwan | H17: =IFERROR(INDEX(City_Lookup!$E$2:$E$66,MATCH($G17,City_Lookup!$D$2:$D$66,0)),"Not Available") -> Bagmati | I17: CCS2 | J17: AC | L17: 22.0 | M17: 22.0 | N17: plug_type='CCS2' | power_type='120Kw - DC, 22Kw - AC' | O17: 2 | P17: Not Available | Q17: https://www.google.com/maps/search/?api=1&query=Paras%20Bus%20Park%2C%20Chitwan%2C%20Paras%20Bus%20Park%2C%20Chitwan | R17: Listed | S17: Not Available | T17: chargingstationsnepal.com (workbook: EV_Station_Data.xlsx, brand/partner network compilation) | U17: NO | V17: YES | W17: 2026-09-03 | X17: +977-1-4153051 | Y17: Operator hotline (web, not station-specific) | Z17: =IF($X17="Not Available","",TRIM(LEFT(SUBSTITUTE(SUBSTITUTE(SUBSTITUTE(SUBSTITUTE(SUBSTITUTE(SUBSTITUTE(SUBSTITUTE($X17," ",""),"-",""),"(",""),")",""),".",""),"+","")&"/","/",REPT(" ",60)),60))) -> 97714153051 | AA17: =IF($Z17="","",IF(ISNUMBER(-$Z17),IF(LEFT($Z17,3)="977",MID($Z17,4,20),$Z17),IF(ISNUMBER(SEARCH("977",$Z17)),MID($Z17,SEARCH("977",$Z17)+3,20),$Z17))) -> 14153051 | AB17: =IF($AA17="","",IF(LEFT($AA17,1)="0",MID($AA17,2,20),$AA17)) -> 14153051 | AC17: =IF($AB17="","Not Available","+977"&$AB17) -> +97714153051 | AD17: =IF($AB17="","Not Available",IF(AND(LEN($AB17)=10,LEFT($AB17,1)="9"),"Mobile",IF(AND(LEN($AB17)>=8,LEN($AB17)<=9),IF(ISNUMBER(SEARCH("/",$X17)),"Landline (multiple lines)","Landline"),"Unrecognised"))) -> Landline | AE17: =IF($AB17="","Not Available",IF(AND(ISNUMBER(-$AB17),$AD17<>"Unrecognised"),"Valid","Check format")) -> Valid
A18: EVNP-0009 | B18: EVNP-0009-P1 | C18: Khurkot, Sindhuli | D18: NEA | E18: Khurkot, Sindhuli | F18: Khurkot, Sindhuli | G18: {=IFERROR(INDEX(City_Lookup!$B$2:$B$297,MATCH(TRUE,ISNUMBER(SEARCH(City_Lookup!$A$2:$A$297,$F18&" "&$E18)),0)),"Not Available")} -> Sindhuli | H18: =IFERROR(INDEX(City_Lookup!$E$2:$E$66,MATCH($G18,City_Lookup!$D$2:$D$66,0)),"Not Available") -> Bagmati | I18: CCS2 | J18: DC | K18: 120.0 | M18: 120.0 | N18: plug_type='CCS2' | power_type='120Kw - DC, 22Kw - AC' | O18: 2 | P18: Not Available | Q18: https://www.google.com/maps/search/?api=1&query=Khurkot%2C%20Sindhuli%2C%20Khurkot%2C%20Sindhuli | R18: Listed | S18: Not Available | T18: chargingstationsnepal.com (workbook: EV_Station_Data.xlsx, brand/partner network compilation) | U18: NO | V18: YES | W18: 2026-09-03 | X18: +977-1-4153051 | Y18: Operator hotline (web, not station-specific) | Z18: =IF($X18="Not Available","",TRIM(LEFT(SUBSTITUTE(SUBSTITUTE(SUBSTITUTE(SUBSTITUTE(SUBSTITUTE(SUBSTITUTE(SUBSTITUTE($X18," ",""),"-",""),"(",""),")",""),".",""),"+","")&"/","/",REPT(" ",60)),60))) -> 97714153051 | AA18: =IF($Z18="","",IF(ISNUMBER(-$Z18),IF(LEFT($Z18,3)="977",MID($Z18,4,20),$Z18),IF(ISNUMBER(SEARCH("977",$Z18)),MID($Z18,SEARCH("977",$Z18)+3,20),$Z18))) -> 14153051 | AB18: =IF($AA18="","",IF(LEFT($AA18,1)="0",MID($AA18,2,20),$AA18)) -> 14153051 | AC18: =IF($AB18="","Not Available","+977"&$AB18) -> +97714153051 | AD18: =IF($AB18="","Not Available",IF(AND(LEN($AB18)=10,LEFT($AB18,1)="9"),"Mobile",IF(AND(LEN($AB18)>=8,LEN($AB18)<=9),IF(ISNUMBER(SEARCH("/",$X18)),"Landline (multiple lines)","Landline"),"Unrecognised"))) -> Landline | AE18: =IF($AB18="","Not Available",IF(AND(ISNUMBER(-$AB18),$AD18<>"Unrecognised"),"Valid","Check format")) -> Valid
A19: EVNP-0009 | B19: EVNP-0009-P2 | C19: Khurkot, Sindhuli | D19: NEA | E19: Khurkot, Sindhuli | F19: Khurkot, Sindhuli | G19: {=IFERROR(INDEX(City_Lookup!$B$2:$B$297,MATCH(TRUE,ISNUMBER(SEARCH(City_Lookup!$A$2:$A$297,$F19&" "&$E19)),0)),"Not Available")} -> Sindhuli | H19: =IFERROR(INDEX(City_Lookup!$E$2:$E$66,MATCH($G19,City_Lookup!$D$2:$D$66,0)),"Not Available") -> Bagmati | I19: CCS2 | J19: AC | L19: 22.0 | M19: 22.0 | N19: plug_type='CCS2' | power_type='120Kw - DC, 22Kw - AC' | O19: 2 | P19: Not Available | Q19: https://www.google.com/maps/search/?api=1&query=Khurkot%2C%20Sindhuli%2C%20Khurkot%2C%20Sindhuli | R19: Listed | S19: Not Available | T19: chargingstationsnepal.com (workbook: EV_Station_Data.xlsx, brand/partner network compilation) | U19: NO | V19: YES | W19: 2026-09-03 | X19: +977-1-4153051 | Y19: Operator hotline (web, not station-specific) | Z19: =IF($X19="Not Available","",TRIM(LEFT(SUBSTITUTE(SUBSTITUTE(SUBSTITUTE(SUBSTITUTE(SUBSTITUTE(SUBSTITUTE(SUBSTITUTE($X19," ",""),"-",""),"(",""),")",""),".",""),"+","")&"/","/",REPT(" ",60)),60))) -> 97714153051 | AA19: =IF($Z19="","",IF(ISNUMBER(-$Z19),IF(LEFT($Z19,3)="977",MID($Z19,4,20),$Z19),IF(ISNUMBER(SEARCH("977",$Z19)),MID($Z19,SEARCH("977",$Z19)+3,20),$Z19))) -> 14153051 | AB19: =IF($AA19="","",IF(LEFT($AA19,1)="0",MID($AA19,2,20),$AA19)) -> 14153051 | AC19: =IF($AB19="","Not Available","+977"&$AB19) -> +97714153051 | AD19: =IF($AB19="","Not Available",IF(AND(LEN($AB19)=10,LEFT($AB19,1)="9"),"Mobile",IF(AND(LEN($AB19)>=8,LEN($AB19)<=9),IF(ISNUMBER(SEARCH("/",$X19)),"Landline (multiple lines)","Landline"),"Unrecognised"))) -> Landline | AE19: =IF($AB19="","Not Available",IF(AND(ISNUMBER(-$AB19),$AD19<>"Unrecognised"),"Valid","Check format")) -> Valid
A20: EVNP-0010 | B20: EVNP-0010-P1 | C20: Sindhuli Bus Park | D20: NEA | E20: Sindhuli Bus Park | F20: Sindhuli Bus Park | G20: {=IFERROR(INDEX(City_Lookup!$B$2:$B$297,MATCH(TRUE,ISNUMBER(SEARCH(City_Lookup!$A$2:$A$297,$F20&" "&$E20)),0)),"Not Available")} -> Sindhuli | H20: =IFERROR(INDEX(City_Lookup!$E$2:$E$66,MATCH($G20,City_Lookup!$D$2:$D$66,0)),"Not Available") -> Bagmati | I20: CCS2 | J20: DC | K20: 120.0 | M20: 120.0 | N20: plug_type='CCS2' | power_type='120Kw - DC, 22Kw - AC' | O20: 2 | P20: Not Available | Q20: https://www.google.com/maps/search/?api=1&query=Sindhuli%20Bus%20Park%2C%20Sindhuli%20Bus%20Park | R20: Listed | S20: Not Available | T20: chargingstationsnepal.com (workbook: EV_Station_Data.xlsx, brand/partner network compilation) | U20: NO | V20: YES | W20: 2026-09-03 | X20: +977-1-4153051 | Y20: Operator hotline (web, not station-specific) | Z20: =IF($X20="Not Available","",TRIM(LEFT(SUBSTITUTE(SUBSTITUTE(SUBSTITUTE(SUBSTITUTE(SUBSTITUTE(SUBSTITUTE(SUBSTITUTE($X20," ",""),"-",""),"(",""),")",""),".",""),"+","")&"/","/",REPT(" ",60)),60))) -> 97714153051 | AA20: =IF($Z20="","",IF(ISNUMBER(-$Z20),IF(LEFT($Z20,3)="977",MID($Z20,4,20),$Z20),IF(ISNUMBER(SEARCH("977",$Z20)),MID($Z20,SEARCH("977",$Z20)+3,20),$Z20))) -> 14153051 | AB20: =IF($AA20="","",IF(LEFT($AA20,1)="0",MID($AA20,2,20),$AA20)) -> 14153051 | AC20: =IF($AB20="","Not Available","+977"&$AB20) -> +97714153051 | AD20: =IF($AB20="","Not Available",IF(AND(LEN($AB20)=10,LEFT($AB20,1)="9"),"Mobile",IF(AND(LEN($AB20)>=8,LEN($AB20)<=9),IF(ISNUMBER(SEARCH("/",$X20)),"Landline (multiple lines)","Landline"),"Unrecognised"))) -> Landline | AE20: =IF($AB20="","Not Available",IF(AND(ISNUMBER(-$AB20),$AD20<>"Unrecognised"),"Valid","Check format")) -> Valid
A21: EVNP-0010 | B21: EVNP-0010-P2 | C21: Sindhuli Bus Park | D21: NEA | E21: Sindhuli Bus Park | F21: Sindhuli Bus Park | G21: {=IFERROR(INDEX(City_Lookup!$B$2:$B$297,MATCH(TRUE,ISNUMBER(SEARCH(City_Lookup!$A$2:$A$297,$F21&" "&$E21)),0)),"Not Available")} -> Sindhuli | H21: =IFERROR(INDEX(City_Lookup!$E$2:$E$66,MATCH($G21,City_Lookup!$D$2:$D$66,0)),"Not Available") -> Bagmati | I21: CCS2 | J21: AC | L21: 22.0 | M21: 22.0 | N21: plug_type='CCS2' | power_type='120Kw - DC, 22Kw - AC' | O21: 2 | P21: Not Available | Q21: https://www.google.com/maps/search/?api=1&query=Sindhuli%20Bus%20Park%2C%20Sindhuli%20Bus%20Park | R21: Listed | S21: Not Available | T21: chargingstationsnepal.com (workbook: EV_Station_Data.xlsx, brand/partner network compilation) | U21: NO | V21: YES | W21: 2026-09-03 | X21: +977-1-4153051 | Y21: Operator hotline (web, not station-specific) | Z21: =IF($X21="Not Available","",TRIM(LEFT(SUBSTITUTE(SUBSTITUTE(SUBSTITUTE(SUBSTITUTE(SUBSTITUTE(SUBSTITUTE(SUBSTITUTE($X21," ",""),"-",""),"(",""),")",""),".",""),"+","")&"/","/",REPT(" ",60)),60))) -> 97714153051 | AA21: =IF($Z21="","",IF(ISNUMBER(-$Z21),IF(LEFT($Z21,3)="977",MID($Z21,4,20),$Z21),IF(ISNUMBER(SEARCH("977",$Z21)),MID($Z21,SEARCH("977",$Z21)+3,20),$Z21))) -> 14153051 | AB21: =IF($AA21="","",IF(LEFT($AA21,1)="0",MID($AA21,2,20),$AA21)) -> 14153051 | AC21: =IF($AB21="","Not Available","+977"&$AB21) -> +97714153051 | AD21: =IF($AB21="","Not Available",IF(AND(LEN($AB21)=10,LEFT($AB21,1)="9"),"Mobile",IF(AND(LEN($AB21)>=8,LEN($AB21)<=9),IF(ISNUMBER(SEARCH("/",$X21)),"Landline (multiple lines)","Landline"),"Unrecognised"))) -> Landline | AE21: =IF($AB21="","Not Available",IF(AND(ISNUMBER(-$AB21),$AD21<>"Unrecognised"),"Valid","Check format")) -> Valid
A22: EVNP-0011 | B22: EVNP-0011-P1 | C22: Bardiwas Local Police Office | D22: NEA | E22: Bardiwas Local Police Office | F22: Bardiwas Local Police Office | G22: {=IFERROR(INDEX(City_Lookup!$B$2:$B$297,MATCH(TRUE,ISNUMBER(SEARCH(City_Lookup!$A$2:$A$297,$F22&" "&$E22)),0)),"Not Available")} -> Mahottari | H22: =IFERROR(INDEX(City_Lookup!$E$2:$E$66,MATCH($G22,City_Lookup!$D$2:$D$66,0)),"Not Available") -> Madhesh | I22: CCS2 | J22: DC | K22: 120.0 | M22: 120.0 | N22: plug_type='CCS2' | power_type='120Kw - DC, 22Kw - AC' | O22: 2 | P22: Not Available | Q22: https://www.google.com/maps/search/?api=1&query=Bardiwas%20Local%20Police%20Office%2C%20Bardiwas%20Local%20Police%20Office | R22: Listed | S22: Not Available | T22: chargingstationsnepal.com (workbook: EV_Station_Data.xlsx, brand/partner network compilation) | U22: NO | V22: YES | W22: 2026-09-03 | X22: +977-1-4153051 | Y22: Operator hotline (web, not station-specific) | Z22: =IF($X22="Not Available","",TRIM(LEFT(SUBSTITUTE(SUBSTITUTE(SUBSTITUTE(SUBSTITUTE(SUBSTITUTE(SUBSTITUTE(SUBSTITUTE($X22," ",""),"-",""),"(",""),")",""),".",""),"+","")&"/","/",REPT(" ",60)),60))) -> 97714153051 | AA22: =IF($Z22="","",IF(ISNUMBER(-$Z22),IF(LEFT($Z22,3)="977",MID($Z22,4,20),$Z22),IF(ISNUMBER(SEARCH("977",$Z22)),MID($Z22,SEARCH("977",$Z22)+3,20),$Z22))) -> 14153051 | AB22: =IF($AA22="","",IF(LEFT($AA22,1)="0",MID($AA22,2,20),$AA22)) -> 14153051 | AC22: =IF($AB22="","Not Available","+977"&$AB22) -> +97714153051 | AD22: =IF($AB22="","Not Available",IF(AND(LEN($AB22)=10,LEFT($AB22,1)="9"),"Mobile",IF(AND(LEN($AB22)>=8,LEN($AB22)<=9),IF(ISNUMBER(SEARCH("/",$X22)),"Landline (multiple lines)","Landline"),"Unrecognised"))) -> Landline | AE22: =IF($AB22="","Not Available",IF(AND(ISNUMBER(-$AB22),$AD22<>"Unrecognised"),"Valid","Check format")) -> Valid
A23: EVNP-0011 | B23: EVNP-0011-P2 | C23: Bardiwas Local Police Office | D23: NEA | E23: Bardiwas Local Police Office | F23: Bardiwas Local Police Office | G23: {=IFERROR(INDEX(City_Lookup!$B$2:$B$297,MATCH(TRUE,ISNUMBER(SEARCH(City_Lookup!$A$2:$A$297,$F23&" "&$E23)),0)),"Not Available")} -> Mahottari | H23: =IFERROR(INDEX(City_Lookup!$E$2:$E$66,MATCH($G23,City_Lookup!$D$2:$D$66,0)),"Not Available") -> Madhesh | I23: CCS2 | J23: AC | L23: 22.0 | M23: 22.0 | N23: plug_type='CCS2' | power_type='120Kw - DC, 22Kw - AC' | O23: 2 | P23: Not Available | Q23: https://www.google.com/maps/search/?api=1&query=Bardiwas%20Local%20Police%20Office%2C%20Bardiwas%20Local%20Police%20Office | R23: Listed | S23: Not Available | T23: chargingstationsnepal.com (workbook: EV_Station_Data.xlsx, brand/partner network compilation) | U23: NO | V23: YES | W23: 2026-09-03 | X23: +977-1-4153051 | Y23: Operator hotline (web, not station-specific) | Z23: =IF($X23="Not Available","",TRIM(LEFT(SUBSTITUTE(SUBSTITUTE(SUBSTITUTE(SUBSTITUTE(SUBSTITUTE(SUBSTITUTE(SUBSTITUTE($X23," ",""),"-",""),"(",""),")",""),".",""),"+","")&"/","/",REPT(" ",60)),60))) -> 97714153051 | AA23: =IF($Z23="","",IF(ISNUMBER(-$Z23),IF(LEFT($Z23,3)="977",MID($Z23,4,20),$Z23),IF(ISNUMBER(SEARCH("977",$Z23)),MID($Z23,SEARCH("977",$Z23)+3,20),$Z23))) -> 14153051 | AB23: =IF($AA23="","",IF(LEFT($AA23,1)="0",MID($AA23,2,20),$AA23)) -> 14153051 | AC23: =IF($AB23="","Not Available","+977"&$AB23) -> +97714153051 | AD23: =IF($AB23="","Not Available",IF(AND(LEN($AB23)=10,LEFT($AB23,1)="9"),"Mobile",IF(AND(LEN($AB23)>=8,LEN($AB23)<=9),IF(ISNUMBER(SEARCH("/",$X23)),"Landline (multiple lines)","Landline"),"Unrecognised"))) -> Landline | AE23: =IF($AB23="","Not Available",IF(AND(ISNUMBER(-$AB23),$AD23<>"Unrecognised"),"Valid","Check format")) -> Valid
A24: EVNP-0012 | B24: EVNP-0012-P1 | C24: Mahottari | D24: NEA | E24: Mahottari | F24: Mahottari | G24: {=IFERROR(INDEX(City_Lookup!$B$2:$B$297,MATCH(TRUE,ISNUMBER(SEARCH(City_Lookup!$A$2:$A$297,$F24&" "&$E24)),0)),"Not Available")} -> Mahottari | H24: =IFERROR(INDEX(City_Lookup!$E$2:$E$66,MATCH($G24,City_Lookup!$D$2:$D$66,0)),"Not Available") -> Madhesh | I24: CCS2 | J24: DC | K24: 120.0 | M24: 120.0 | N24: plug_type='CCS2' | power_type='120Kw - DC, 22Kw - AC' | O24: 2 | P24: Not Available | Q24: https://www.google.com/maps/search/?api=1&query=Mahottari%2C%20Mahottari | R24: Listed | S24: Not Available | T24: chargingstationsnepal.com (workbook: EV_Station_Data.xlsx, brand/partner network compilation) | U24: NO | V24: YES | W24: 2026-09-03 | X24: +977-1-4153051 | Y24: Operator hotline (web, not station-specific) | Z24: =IF($X24="Not Available","",TRIM(LEFT(SUBSTITUTE(SUBSTITUTE(SUBSTITUTE(SUBSTITUTE(SUBSTITUTE(SUBSTITUTE(SUBSTITUTE($X24," ",""),"-",""),"(",""),")",""),".",""),"+","")&"/","/",REPT(" ",60)),60))) -> 97714153051 | AA24: =IF($Z24="","",IF(ISNUMBER(-$Z24),IF(LEFT($Z24,3)="977",MID($Z24,4,20),$Z24),IF(ISNUMBER(SEARCH("977",$Z24)),MID($Z24,SEARCH("977",$Z24)+3,20),$Z24))) -> 14153051 | AB24: =IF($AA24="","",IF(LEFT($AA24,1)="0",MID($AA24,2,20),$AA24)) -> 14153051 | AC24: =IF($AB24="","Not Available","+977"&$AB24) -> +97714153051 | AD24: =IF($AB24="","Not Available",IF(AND(LEN($AB24)=10,LEFT($AB24,1)="9"),"Mobile",IF(AND(LEN($AB24)>=8,LEN($AB24)<=9),IF(ISNUMBER(SEARCH("/",$X24)),"Landline (multiple lines)","Landline"),"Unrecognised"))) -> Landline | AE24: =IF($AB24="","Not Available",IF(AND(ISNUMBER(-$AB24),$AD24<>"Unrecognised"),"Valid","Check format")) -> Valid
A25: EVNP-0012 | B25: EVNP-0012-P2 | C25: Mahottari | D25: NEA | E25: Mahottari | F25: Mahottari | G25: {=IFERROR(INDEX(City_Lookup!$B$2:$B$297,MATCH(TRUE,ISNUMBER(SEARCH(City_Lookup!$A$2:$A$297,$F25&" "&$E25)),0)),"Not Available")} -> Mahottari | H25: =IFERROR(INDEX(City_Lookup!$E$2:$E$66,MATCH($G25,City_Lookup!$D$2:$D$66,0)),"Not Available") -> Madhesh | I25: CCS2 | J25: AC | L25: 22.0 | M25: 22.0 | N25: plug_type='CCS2' | power_type='120Kw - DC, 22Kw - AC' | O25: 2 | P25: Not Available | Q25: https://www.google.com/maps/search/?api=1&query=Mahottari%2C%20Mahottari | R25: Listed | S25: Not Available | T25: chargingstationsnepal.com (workbook: EV_Station_Data.xlsx, brand/partner network compilation) | U25: NO | V25: YES | W25: 2026-09-03 | X25: +977-1-4153051 | Y25: Operator hotline (web, not station-specific) | Z25: =IF($X25="Not Available","",TRIM(LEFT(SUBSTITUTE(SUBSTITUTE(SUBSTITUTE(SUBSTITUTE(SUBSTITUTE(SUBSTITUTE(SUBSTITUTE($X25," ",""),"-",""),"(",""),")",""),".",""),"+","")&"/","/",REPT(" ",60)),60))) -> 97714153051 | AA25: =IF($Z25="","",IF(ISNUMBER(-$Z25),IF(LEFT($Z25,3)="977",MID($Z25,4,20),$Z25),IF(ISNUMBER(SEARCH("977",$Z25)),MID($Z25,SEARCH("977",$Z25)+3,20),$Z25))) -> 14153051 | AB25: =IF($AA25="","",IF(LEFT($AA25,1)="0",MID($AA25,2,20),$AA25)) -> 14153051 | AC25: =IF($AB25="","Not Available","+977"&$AB25) -> +97714153051 | AD25: =IF($AB25="","Not Available",IF(AND(LEN($AB25)=10,LEFT($AB25,1)="9"),"Mobile",IF(AND(LEN($AB25)>=8,LEN($AB25)<=9),IF(ISNUMBER(SEARCH("/",$X25)),"Landline (multiple lines)","Landline"),"Unrecognised"))) -> Landline | AE25: =IF($AB25="","Not Available",IF(AND(ISNUMBER(-$AB25),$AD25<>"Unrecognised"),"Valid","Check format")) -> Valid
A26: EVNP-0013 | B26: EVNP-0013-P1 | C26: Hariban, Sarlahi | D26: NEA | E26: Hariban, Sarlahi | F26: Hariban, Sarlahi | G26: {=IFERROR(INDEX(City_Lookup!$B$2:$B$297,MATCH(TRUE,ISNUMBER(SEARCH(City_Lookup!$A$2:$A$297,$F26&" "&$E26)),0)),"Not Available")} -> Sarlahi | H26: =IFERROR(INDEX(City_Lookup!$E$2:$E$66,MATCH($G26,City_Lookup!$D$2:$D$66,0)),"Not Available") -> Madhesh | I26: CCS2 | J26: DC | K26: 120.0 | M26: 120.0 | N26: plug_type='CCS2' | power_type='120Kw - DC, 22Kw - AC' | O26: 2 | P26: Not Available | Q26: https://www.google.com/maps/search/?api=1&query=Hariban%2C%20Sarlahi%2C%20Hariban%2C%20Sarlahi | R26: Listed | S26: Not Available | T26: chargingstationsnepal.com (workbook: EV_Station_Data.xlsx, brand/partner network compilation) | U26: NO | V26: YES | W26: 2026-09-03 | X26: +977-1-4153051 | Y26: Operator hotline (web, not station-specific) | Z26: =IF($X26="Not Available","",TRIM(LEFT(SUBSTITUTE(SUBSTITUTE(SUBSTITUTE(SUBSTITUTE(SUBSTITUTE(SUBSTITUTE(SUBSTITUTE($X26," ",""),"-",""),"(",""),")",""),".",""),"+","")&"/","/",REPT(" ",60)),60))) -> 97714153051 | AA26: =IF($Z26="","",IF(ISNUMBER(-$Z26),IF(LEFT($Z26,3)="977",MID($Z26,4,20),$Z26),IF(ISNUMBER(SEARCH("977",$Z26)),MID($Z26,SEARCH("977",$Z26)+3,20),$Z26))) -> 14153051 | AB26: =IF($AA26="","",IF(LEFT($AA26,1)="0",MID($AA26,2,20),$AA26)) -> 14153051 | AC26: =IF($AB26="","Not Available","+977"&$AB26) -> +97714153051 | AD26: =IF($AB26="","Not Available",IF(AND(LEN($AB26)=10,LEFT($AB26,1)="9"),"Mobile",IF(AND(LEN($AB26)>=8,LEN($AB26)<=9),IF(ISNUMBER(SEARCH("/",$X26)),"Landline (multiple lines)","Landline"),"Unrecognised"))) -> Landline | AE26: =IF($AB26="","Not Available",IF(AND(ISNUMBER(-$AB26),$AD26<>"Unrecognised"),"Valid","Check format")) -> Valid
A27: EVNP-0013 | B27: EVNP-0013-P2 | C27: Hariban, Sarlahi | D27: NEA | E27: Hariban, Sarlahi | F27: Hariban, Sarlahi | G27: {=IFERROR(INDEX(City_Lookup!$B$2:$B$297,MATCH(TRUE,ISNUMBER(SEARCH(City_Lookup!$A$2:$A$297,$F27&" "&$E27)),0)),"Not Available")} -> Sarlahi | H27: =IFERROR(INDEX(City_Lookup!$E$2:$E$66,MATCH($G27,City_Lookup!$D$2:$D$66,0)),"Not Available") -> Madhesh | I27: CCS2 | J27: AC | L27: 22.0 | M27: 22.0 | N27: plug_type='CCS2' | power_type='120Kw - DC, 22Kw - AC' | O27: 2 | P27: Not Available | Q27: https://www.google.com/maps/search/?api=1&query=Hariban%2C%20Sarlahi%2C%20Hariban%2C%20Sarlahi | R27: Listed | S27: Not Available | T27: chargingstationsnepal.com (workbook: EV_Station_Data.xlsx, brand/partner network compilation) | U27: NO | V27: YES | W27: 2026-09-03 | X27: +977-1-4153051 | Y27: Operator hotline (web, not station-specific) | Z27: =IF($X27="Not Available","",TRIM(LEFT(SUBSTITUTE(SUBSTITUTE(SUBSTITUTE(SUBSTITUTE(SUBSTITUTE(SUBSTITUTE(SUBSTITUTE($X27," ",""),"-",""),"(",""),")",""),".",""),"+","")&"/","/",REPT(" ",60)),60))) -> 97714153051 | AA27: =IF($Z27="","",IF(ISNUMBER(-$Z27),IF(LEFT($Z27,3)="977",MID($Z27,4,20),$Z27),IF(ISNUMBER(SEARCH("977",$Z27)),MID($Z27,SEARCH("977",$Z27)+3,20),$Z27))) -> 14153051 | AB27: =IF($AA27="","",IF(LEFT($AA27,1)="0",MID($AA27,2,20),$AA27)) -> 14153051 | AC27: =IF($AB27="","Not Available","+977"&$AB27) -> +97714153051 | AD27: =IF($AB27="","Not Available",IF(AND(LEN($AB27)=10,LEFT($AB27,1)="9"),"Mobile",IF(AND(LEN($AB27)>=8,LEN($AB27)<=9),IF(ISNUMBER(SEARCH("/",$X27)),"Landline (multiple lines)","Landline"),"Unrecognised"))) -> Landline | AE27: =IF($AB27="","Not Available",IF(AND(ISNUMBER(-$AB27),$AD27<>"Unrecognised"),"Valid","Check format")) -> Valid
A28: EVNP-0014 | B28: EVNP-0014-P1 | C28: Inaruwa Bus Park, Sunsari | D28: NEA | E28: Inaruwa Bus Park, Sunsari | F28: Inaruwa Bus Park, Sunsari | G28: {=IFERROR(INDEX(City_Lookup!$B$2:$B$297,MATCH(TRUE,ISNUMBER(SEARCH(City_Lookup!$A$2:$A$297,$F28&" "&$E28)),0)),"Not Available")} -> Sunsari | H28: =IFERROR(INDEX(City_Lookup!$E$2:$E$66,MATCH($G28,City_Lookup!$D$2:$D$66,0)),"Not Available") -> Koshi | I28: CCS2 | J28: DC | K28: 120.0 | M28: 120.0 | N28: plug_type='CCS2' | power_type='120Kw - DC, 22Kw - AC' | O28: 2 | P28: Not Available | Q28: https://www.google.com/maps/search/?api=1&query=Inaruwa%20Bus%20Park%2C%20Sunsari%2C%20Inaruwa%20Bus%20Park%2C%20Sunsari | R28: Listed | S28: Not Available | T28: chargingstationsnepal.com (workbook: EV_Station_Data.xlsx, brand/partner network compilation) | U28: NO | V28: YES | W28: 2026-09-03 | X28: +977-1-4153051 | Y28: Operator hotline (web, not station-specific) | Z28: =IF($X28="Not Available","",TRIM(LEFT(SUBSTITUTE(SUBSTITUTE(SUBSTITUTE(SUBSTITUTE(SUBSTITUTE(SUBSTITUTE(SUBSTITUTE($X28," ",""),"-",""),"(",""),")",""),".",""),"+","")&"/","/",REPT(" ",60)),60))) -> 97714153051 | AA28: =IF($Z28="","",IF(ISNUMBER(-$Z28),IF(LEFT($Z28,3)="977",MID($Z28,4,20),$Z28),IF(ISNUMBER(SEARCH("977",$Z28)),MID($Z28,SEARCH("977",$Z28)+3,20),$Z28))) -> 14153051 | AB28: =IF($AA28="","",IF(LEFT($AA28,1)="0",MID($AA28,2,20),$AA28)) -> 14153051 | AC28: =IF($AB28="","Not Available","+977"&$AB28) -> +97714153051 | AD28: =IF($AB28="","Not Available",IF(AND(LEN($AB28)=10,LEFT($AB28,1)="9"),"Mobile",IF(AND(LEN($AB28)>=8,LEN($AB28)<=9),IF(ISNUMBER(SEARCH("/",$X28)),"Landline (multiple lines)","Landline"),"Unrecognised"))) -> Landline | AE28: =IF($AB28="","Not Available",IF(AND(ISNUMBER(-$AB28),$AD28<>"Unrecognised"),"Valid","Check format")) -> Valid
A29: EVNP-0014 | B29: EVNP-0014-P2 | C29: Inaruwa Bus Park, Sunsari | D29: NEA | E29: Inaruwa Bus Park, Sunsari | F29: Inaruwa Bus Park, Sunsari | G29: {=IFERROR(INDEX(City_Lookup!$B$2:$B$297,MATCH(TRUE,ISNUMBER(SEARCH(City_Lookup!$A$2:$A$297,$F29&" "&$E29)),0)),"Not Available")} -> Sunsari | H29: =IFERROR(INDEX(City_Lookup!$E$2:$E$66,MATCH($G29,City_Lookup!$D$2:$D$66,0)),"Not Available") -> Koshi | I29: CCS2 | J29: AC | L29: 22.0 | M29: 22.0 | N29: plug_type='CCS2' | power_type='120Kw - DC, 22Kw - AC' | O29: 2 | P29: Not Available | Q29: https://www.google.com/maps/search/?api=1&query=Inaruwa%20Bus%20Park%2C%20Sunsari%2C%20Inaruwa%20Bus%20Park%2C%20Sunsari | R29: Listed | S29: Not Available | T29: chargingstationsnepal.com (workbook: EV_Station_Data.xlsx, brand/partner network compilation) | U29: NO | V29: YES | W29: 2026-09-03 | X29: +977-1-4153051 | Y29: Operator hotline (web, not station-specific) | Z29: =IF($X29="Not Available","",TRIM(LEFT(SUBSTITUTE(SUBSTITUTE(SUBSTITUTE(SUBSTITUTE(SUBSTITUTE(SUBSTITUTE(SUBSTITUTE($X29," ",""),"-",""),"(",""),")",""),".",""),"+","")&"/","/",REPT(" ",60)),60))) -> 97714153051 | AA29: =IF($Z29="","",IF(ISNUMBER(-$Z29),IF(LEFT($Z29,3)="977",MID($Z29,4,20),$Z29),IF(ISNUMBER(SEARCH("977",$Z29)),MID($Z29,SEARCH("977",$Z29)+3,20),$Z29))) -> 14153051 | AB29: =IF($AA29="","",IF(LEFT($AA29,1)="0",MID($AA29,2,20),$AA29)) -> 14153051 | AC29: =IF($AB29="","Not Available","+977"&$AB29) -> +97714153051 | AD29: =IF($AB29="","Not Available",IF(AND(LEN($AB29)=10,LEFT($AB29,1)="9"),"Mobile",IF(AND(LEN($AB29)>=8,LEN($AB29)<=9),IF(ISNUMBER(SEARCH("/",$X29)),"Landline (multiple lines)","Landline"),"Unrecognised"))) -> Landline | AE29: =IF($AB29="","Not Available",IF(AND(ISNUMBER(-$AB29),$AD29<>"Unrecognised"),"Valid","Check format")) -> Valid
A30: EVNP-0015 | B30: EVNP-0015-P1 | C30: Police Petrol Pump Lahan, Siraha | D30: NEA | E30: Police Petrol Pump Lahan, Siraha | F30: Police Petrol Pump Lahan, Siraha | G30: {=IFERROR(INDEX(City_Lookup!$B$2:$B$297,MATCH(TRUE,ISNUMBER(SEARCH(City_Lookup!$A$2:$A$297,$F30&" "&$E30)),0)),"Not Available")} -> Siraha | H30: =IFERROR(INDEX(City_Lookup!$E$2:$E$66,MATCH($G30,City_Lookup!$D$2:$D$66,0)),"Not Available") -> Madhesh | I30: CCS2 | J30: DC | K30: 120.0 | M30: 120.0 | N30: plug_type='CCS2' | power_type='120Kw - DC, 22Kw - AC' | O30: 2 | P30: Not Available | Q30: https://www.google.com/maps/search/?api=1&query=Police%20Petrol%20Pump%20Lahan%2C%20Siraha%2C%20Police%20Petrol%20Pump%20Lahan%2C%20Siraha | R30: Listed | S30: Not Available | T30: chargingstationsnepal.com (workbook: EV_Station_Data.xlsx, brand/partner network compilation) | U30: NO | V30: YES | W30: 2026-09-03 | X30: +977-1-4153051 | Y30: Operator hotline (web, not station-specific) | Z30: =IF($X30="Not Available","",TRIM(LEFT(SUBSTITUTE(SUBSTITUTE(SUBSTITUTE(SUBSTITUTE(SUBSTITUTE(SUBSTITUTE(SUBSTITUTE($X30," ",""),"-",""),"(",""),")",""),".",""),"+","")&"/","/",REPT(" ",60)),60))) -> 97714153051 | AA30: =IF($Z30="","",IF(ISNUMBER(-$Z30),IF(LEFT($Z30,3)="977",MID($Z30,4,20),$Z30),IF(ISNUMBER(SEARCH("977",$Z30)),MID($Z30,SEARCH("977",$Z30)+3,20),$Z30))) -> 14153051 | AB30: =IF($AA30="","",IF(LEFT($AA30,1)="0",MID($AA30,2,20),$AA30)) -> 14153051 | AC30: =IF($AB30="","Not Available","+977"&$AB30) -> +97714153051 | AD30: =IF($AB30="","Not Available",IF(AND(LEN($AB30)=10,LEFT($AB30,1)="9"),"Mobile",IF(AND(LEN($AB30)>=8,LEN($AB30)<=9),IF(ISNUMBER(SEARCH("/",$X30)),"Landline (multiple lines)","Landline"),"Unrecognised"))) -> Landline | AE30: =IF($AB30="","Not Available",IF(AND(ISNUMBER(-$AB30),$AD30<>"Unrecognised"),"Valid","Check format")) -> Valid
A31: EVNP-0015 | B31: EVNP-0015-P2 | C31: Police Petrol Pump Lahan, Siraha | D31: NEA | E31: Police Petrol Pump Lahan, Siraha | F31: Police Petrol Pump Lahan, Siraha | G31: {=IFERROR(INDEX(City_Lookup!$B$2:$B$297,MATCH(TRUE,ISNUMBER(SEARCH(City_Lookup!$A$2:$A$297,$F31&" "&$E31)),0)),"Not Available")} -> Siraha | H31: =IFERROR(INDEX(City_Lookup!$E$2:$E$66,MATCH($G31,City_Lookup!$D$2:$D$66,0)),"Not Available") -> Madhesh | I31: CCS2 | J31: AC | L31: 22.0 | M31: 22.0 | N31: plug_type='CCS2' | power_type='120Kw - DC, 22Kw - AC' | O31: 2 | P31: Not Available | Q31: https://www.google.com/maps/search/?api=1&query=Police%20Petrol%20Pump%20Lahan%2C%20Siraha%2C%20Police%20Petrol%20Pump%20Lahan%2C%20Siraha | R31: Listed | S31: Not Available | T31: chargingstationsnepal.com (workbook: EV_Station_Data.xlsx, brand/partner network compilation) | U31: NO | V31: YES | W31: 2026-09-03 | X31: +977-1-4153051 | Y31: Operator hotline (web, not station-specific) | Z31: =IF($X31="Not Available","",TRIM(LEFT(SUBSTITUTE(SUBSTITUTE(SUBSTITUTE(SUBSTITUTE(SUBSTITUTE(SUBSTITUTE(SUBSTITUTE($X31," ",""),"-",""),"(",""),")",""),".",""),"+","")&"/","/",REPT(" ",60)),60))) -> 97714153051 | AA31: =IF($Z31="","",IF(ISNUMBER(-$Z31),IF(LEFT($Z31,3)="977",MID($Z31,4,20),$Z31),IF(ISNUMBER(SEARCH("977",$Z31)),MID($Z31,SEARCH("977",$Z31)+3,20),$Z31))) -> 14153051 | AB31: =IF($AA31="","",IF(LEFT($AA31,1)="0",MID($AA31,2,20),$AA31)) -> 14153051 | AC31: =IF($AB31="","Not Available","+977"&$AB31) -> +97714153051 | AD31: =IF($AB31="","Not Available",IF(AND(LEN($AB31)=10,LEFT($AB31,1)="9"),"Mobile",IF(AND(LEN($AB31)>=8,LEN($AB31)<=9),IF(ISNUMBER(SEARCH("/",$X31)),"Landline (multiple lines)","Landline"),"Unrecognised"))) -> Landline | AE31: =IF($AB31="","Not Available",IF(AND(ISNUMBER(-$AB31),$AD31<>"Unrecognised"),"Valid","Check format")) -> Valid
A32: EVNP-0016 | B32: EVNP-0016-P1 | C32: Kalika Fuel Station, Kaski | D32: NEA | E32: Kalika Fuel Station, Kaski | F32: Kalika Fuel Station, Kaski | G32: {=IFERROR(INDEX(City_Lookup!$B$2:$B$297,MATCH(TRUE,ISNUMBER(SEARCH(City_Lookup!$A$2:$A$297,$F32&" "&$E32)),0)),"Not Available")} -> Kaski | H32: =IFERROR(INDEX(City_Lookup!$E$2:$E$66,MATCH($G32,City_Lookup!$D$2:$D$66,0)),"Not Available") -> Gandaki | I32: CCS2 | J32: DC | K32: 120.0 | M32: 120.0 | N32: plug_type='CCS2' | power_type='120Kw - DC, 22Kw - AC' | O32: 2 | P32: Not Available | Q32: https://www.google.com/maps/search/?api=1&query=Kalika%20Fuel%20Station%2C%20Kaski%2C%20Kalika%20Fuel%20Station%2C%20Kaski | R32: Listed | S32: Not Available | T32: chargingstationsnepal.com (workbook: EV_Station_Data.xlsx, brand/partner network compilation) | U32: NO | V32: YES | W32: 2026-09-03 | X32: +977-1-4153051 | Y32: Operator hotline (web, not station-specific) | Z32: =IF($X32="Not Available","",TRIM(LEFT(SUBSTITUTE(SUBSTITUTE(SUBSTITUTE(SUBSTITUTE(SUBSTITUTE(SUBSTITUTE(SUBSTITUTE($X32," ",""),"-",""),"(",""),")",""),".",""),"+","")&"/","/",REPT(" ",60)),60))) -> 97714153051 | AA32: =IF($Z32="","",IF(ISNUMBER(-$Z32),IF(LEFT($Z32,3)="977",MID($Z32,4,20),$Z32),IF(ISNUMBER(SEARCH("977",$Z32)),MID($Z32,SEARCH("977",$Z32)+3,20),$Z32))) -> 14153051 | AB32: =IF($AA32="","",IF(LEFT($AA32,1)="0",MID($AA32,2,20),$AA32)) -> 14153051 | AC32: =IF($AB32="","Not Available","+977"&$AB32) -> +97714153051 | AD32: =IF($AB32="","Not Available",IF(AND(LEN($AB32)=10,LEFT($AB32,1)="9"),"Mobile",IF(AND(LEN($AB32)>=8,LEN($AB32)<=9),IF(ISNUMBER(SEARCH("/",$X32)),"Landline (multiple lines)","Landline"),"Unrecognised"))) -> Landline | AE32: =IF($AB32="","Not Available",IF(AND(ISNUMBER(-$AB32),$AD32<>"Unrecognised"),"Valid","Check format")) -> Valid
A33: EVNP-0016 | B33: EVNP-0016-P2 | C33: Kalika Fuel Station, Kaski | D33: NEA | E33: Kalika Fuel Station, Kaski | F33: Kalika Fuel Station, Kaski | G33: {=IFERROR(INDEX(City_Lookup!$B$2:$B$297,MATCH(TRUE,ISNUMBER(SEARCH(City_Lookup!$A$2:$A$297,$F33&" "&$E33)),0)),"Not Available")} -> Kaski | H33: =IFERROR(INDEX(City_Lookup!$E$2:$E$66,MATCH($G33,City_Lookup!$D$2:$D$66,0)),"Not Available") -> Gandaki | I33: CCS2 | J33: AC | L33: 22.0 | M33: 22.0 | N33: plug_type='CCS2' | power_type='120Kw - DC, 22Kw - AC' | O33: 2 | P33: Not Available | Q33: https://www.google.com/maps/search/?api=1&query=Kalika%20Fuel%20Station%2C%20Kaski%2C%20Kalika%20Fuel%20Station%2C%20Kaski | R33: Listed | S33: Not Available | T33: chargingstationsnepal.com (workbook: EV_Station_Data.xlsx, brand/partner network compilation) | U33: NO | V33: YES | W33: 2026-09-03 | X33: +977-1-4153051 | Y33: Operator hotline (web, not station-specific) | Z33: =IF($X33="Not Available","",TRIM(LEFT(SUBSTITUTE(SUBSTITUTE(SUBSTITUTE(SUBSTITUTE(SUBSTITUTE(SUBSTITUTE(SUBSTITUTE($X33," ",""),"-",""),"(",""),")",""),".",""),"+","")&"/","/",REPT(" ",60)),60))) -> 97714153051 | AA33: =IF($Z33="","",IF(ISNUMBER(-$Z33),IF(LEFT($Z33,3)="977",MID($Z33,4,20),$Z33),IF(ISNUMBER(SEARCH("977",$Z33)),MID($Z33,SEARCH("977",$Z33)+3,20),$Z33))) -> 14153051 | AB33: =IF($AA33="","",IF(LEFT($AA33,1)="0",MID($AA33,2,20),$AA33)) -> 14153051 | AC33: =IF($AB33="","Not Available","+977"&$AB33) -> +97714153051 | AD33: =IF($AB33="","Not Available",IF(AND(LEN($AB33)=10,LEFT($AB33,1)="9"),"Mobile",IF(AND(LEN($AB33)>=8,LEN($AB33)<=9),IF(ISNUMBER(SEARCH("/",$X33)),"Landline (multiple lines)","Landline"),"Unrecognised"))) -> Landline | AE33: =IF($AB33="","Not Available",IF(AND(ISNUMBER(-$AB33),$AD33<>"Unrecognised"),"Valid","Check format")) -> Valid
A34: EVNP-0017 | B34: EVNP-0017-P1 | C34: Damak Bus Park, Jhapa | D34: NEA | E34: Damak Bus Park, Jhapa | F34: Damak Bus Park, Jhapa | G34: {=IFERROR(INDEX(City_Lookup!$B$2:$B$297,MATCH(TRUE,ISNUMBER(SEARCH(City_Lookup!$A$2:$A$297,$F34&" "&$E34)),0)),"Not Available")} -> Jhapa | H34: =IFERROR(INDEX(City_Lookup!$E$2:$E$66,MATCH($G34,City_Lookup!$D$2:$D$66,0)),"Not Available") -> Koshi | I34: CCS2 | J34: DC | K34: 120.0 | M34: 120.0 | N34: plug_type='CCS2' | power_type='120Kw - DC, 22Kw - AC' | O34: 2 | P34: Not Available | Q34: https://www.google.com/maps/search/?api=1&query=Damak%20Bus%20Park%2C%20Jhapa%2C%20Damak%20Bus%20Park%2C%20Jhapa | R34: Listed | S34: Not Available | T34: chargingstationsnepal.com (workbook: EV_Station_Data.xlsx, brand/partner network compilation) | U34: NO | V34: YES | W34: 2026-09-03 | X34: +977-1-4153051 | Y34: Operator hotline (web, not station-specific) | Z34: =IF($X34="Not Available","",TRIM(LEFT(SUBSTITUTE(SUBSTITUTE(SUBSTITUTE(SUBSTITUTE(SUBSTITUTE(SUBSTITUTE(SUBSTITUTE($X34," ",""),"-",""),"(",""),")",""),".",""),"+","")&"/","/",REPT(" ",60)),60))) -> 97714153051 | AA34: =IF($Z34="","",IF(ISNUMBER(-$Z34),IF(LEFT($Z34,3)="977",MID($Z34,4,20),$Z34),IF(ISNUMBER(SEARCH("977",$Z34)),MID($Z34,SEARCH("977",$Z34)+3,20),$Z34))) -> 14153051 | AB34: =IF($AA34="","",IF(LEFT($AA34,1)="0",MID($AA34,2,20),$AA34)) -> 14153051 | AC34: =IF($AB34="","Not Available","+977"&$AB34) -> +97714153051 | AD34: =IF($AB34="","Not Available",IF(AND(LEN($AB34)=10,LEFT($AB34,1)="9"),"Mobile",IF(AND(LEN($AB34)>=8,LEN($AB34)<=9),IF(ISNUMBER(SEARCH("/",$X34)),"Landline (multiple lines)","Landline"),"Unrecognised"))) -> Landline | AE34: =IF($AB34="","Not Available",IF(AND(ISNUMBER(-$AB34),$AD34<>"Unrecognised"),"Valid","Check format")) -> Valid
A35: EVNP-0017 | B35: EVNP-0017-P2 | C35: Damak Bus Park, Jhapa | D35: NEA | E35: Damak Bus Park, Jhapa | F35: Damak Bus Park, Jhapa | G35: {=IFERROR(INDEX(City_Lookup!$B$2:$B$297,MATCH(TRUE,ISNUMBER(SEARCH(City_Lookup!$A$2:$A$297,$F35&" "&$E35)),0)),"Not Available")} -> Jhapa | H35: =IFERROR(INDEX(City_Lookup!$E$2:$E$66,MATCH($G35,City_Lookup!$D$2:$D$66,0)),"Not Available") -> Koshi | I35: CCS2 | J35: AC | L35: 22.0 | M35: 22.0 | N35: plug_type='CCS2' | power_type='120Kw - DC, 22Kw - AC' | O35: 2 | P35: Not Available | Q35: https://www.google.com/maps/search/?api=1&query=Damak%20Bus%20Park%2C%20Jhapa%2C%20Damak%20Bus%20Park%2C%20Jhapa | R35: Listed | S35: Not Available | T35: chargingstationsnepal.com (workbook: EV_Station_Data.xlsx, brand/partner network compilation) | U35: NO | V35: YES | W35: 2026-09-03 | X35: +977-1-4153051 | Y35: Operator hotline (web, not station-specific) | Z35: =IF($X35="Not Available","",TRIM(LEFT(SUBSTITUTE(SUBSTITUTE(SUBSTITUTE(SUBSTITUTE(SUBSTITUTE(SUBSTITUTE(SUBSTITUTE($X35," ",""),"-",""),"(",""),")",""),".",""),"+","")&"/","/",REPT(" ",60)),60))) -> 97714153051 | AA35: =IF($Z35="","",IF(ISNUMBER(-$Z35),IF(LEFT($Z35,3)="977",MID($Z35,4,20),$Z35),IF(ISNUMBER(SEARCH("977",$Z35)),MID($Z35,SEARCH("977",$Z35)+3,20),$Z35))) -> 14153051 | AB35: =IF($AA35="","",IF(LEFT($AA35,1)="0",MID($AA35,2,20),$AA35)) -> 14153051 | AC35: =IF($AB35="","Not Available","+977"&$AB35) -> +97714153051 | AD35: =IF($AB35="","Not Available",IF(AND(LEN($AB35)=10,LEFT($AB35,1)="9"),"Mobile",IF(AND(LEN($AB35)>=8,LEN($AB35)<=9),IF(ISNUMBER(SEARCH("/",$X35)),"Landline (multiple lines)","Landline"),"Unrecognised"))) -> Landline | AE35: =IF($AB35="","Not Available",IF(AND(ISNUMBER(-$AB35),$AD35<>"Unrecognised"),"Valid","Check format")) -> Valid
